# Generated by Django 4.2.6 on 2024-07-21 13:28

from django.conf import settings
import django.core.validators
from django.db import migrations, models
import django.db.models.deletion


class Migration(migrations.Migration):

    initial = True

    dependencies = [
        ('services', '0001_initial'),
        migrations.swappable_dependency(settings.AUTH_USER_MODEL),
    ]

    operations = [
        migrations.CreateModel(
            name='Cart',
            fields=[
                ('id', models.BigAutoField(auto_created=True, primary_key=True, serialize=False, verbose_name='ID')),
                ('quantity', models.PositiveIntegerField(validators=[django.core.validators.MinValueValidator(1)], verbose_name='Quantity')),
                ('created_at', models.DateTimeField(auto_now_add=True, verbose_name='Created At')),
                ('updated_at', models.DateTimeField(auto_now=True, verbose_name='Updated At')),
                ('service', models.ForeignKey(on_delete=django.db.models.deletion.CASCADE, related_name='carts', to='services.service', verbose_name='Service')),
                ('user', models.ForeignKey(on_delete=django.db.models.deletion.CASCADE, related_name='carts', to=settings.AUTH_USER_MODEL, verbose_name='User')),
            ],
            options={
                'verbose_name': 'Cart',
                'verbose_name_plural': 'Carts',
            },
        ),
        migrations.AddConstraint(
            model_name='cart',
            constraint=models.UniqueConstraint(fields=('user', 'service'), name='unique_cart', violation_error_message='This service is already in your cart.'),
        ),
    ]
